Traceback (most recent call last):
  File "/home/khuyen/book/venv/lib/python3.8/site-packages/jupyter_cache/executors/utils.py", line 51, in single_nb_execution
    executenb(
  File "/home/khuyen/book/venv/lib/python3.8/site-packages/nbclient/client.py", line 1117, in execute
    return NotebookClient(nb=nb, resources=resources, km=km, **kwargs).execute()
  File "/home/khuyen/book/venv/lib/python3.8/site-packages/nbclient/util.py", line 78, in wrapped
    return just_run(coro(*args, **kwargs))
  File "/home/khuyen/book/venv/lib/python3.8/site-packages/nbclient/util.py", line 57, in just_run
    return loop.run_until_complete(coro)
  File "/usr/lib/python3.8/asyncio/base_events.py", line 616, in run_until_complete
    return future.result()
  File "/home/khuyen/book/venv/lib/python3.8/site-packages/nbclient/client.py", line 558, in async_execute
    await self.async_execute_cell(
  File "/home/khuyen/book/venv/lib/python3.8/site-packages/nbclient/client.py", line 862, in async_execute_cell
    self._check_raise_for_error(cell, exec_reply)
  File "/home/khuyen/book/venv/lib/python3.8/site-packages/nbclient/client.py", line 765, in _check_raise_for_error
    raise CellExecutionError.from_cell_and_msg(cell, exec_reply_content)
nbclient.exceptions.CellExecutionError: An error occurred while executing the following cell:
------------------
from pandas.testing import assert_frame_equal
import pandas as pd 


df1 = pd.DataFrame({'coll': [1,2,3], 'col2': [4,5,6]})
df2 = pd.DataFrame({'coll': [1,3,4], 'col2': [4,5,6]})
assert_frame_equal(df1, df2)
------------------

[0;31m---------------------------------------------------------------------------[0m
[0;31mAssertionError[0m                            Traceback (most recent call last)
[0;32m/tmp/ipykernel_158873/3851828215.py[0m in [0;36m<module>[0;34m[0m
[1;32m      5[0m [0mdf1[0m [0;34m=[0m [0mpd[0m[0;34m.[0m[0mDataFrame[0m[0;34m([0m[0;34m{[0m[0;34m'coll'[0m[0;34m:[0m [0;34m[[0m[0;36m1[0m[0;34m,[0m[0;36m2[0m[0;34m,[0m[0;36m3[0m[0;34m][0m[0;34m,[0m [0;34m'col2'[0m[0;34m:[0m [0;34m[[0m[0;36m4[0m[0;34m,[0m[0;36m5[0m[0;34m,[0m[0;36m6[0m[0;34m][0m[0;34m}[0m[0;34m)[0m[0;34m[0m[0;34m[0m[0m
[1;32m      6[0m [0mdf2[0m [0;34m=[0m [0mpd[0m[0;34m.[0m[0mDataFrame[0m[0;34m([0m[0;34m{[0m[0;34m'coll'[0m[0;34m:[0m [0;34m[[0m[0;36m1[0m[0;34m,[0m[0;36m3[0m[0;34m,[0m[0;36m4[0m[0;34m][0m[0;34m,[0m [0;34m'col2'[0m[0;34m:[0m [0;34m[[0m[0;36m4[0m[0;34m,[0m[0;36m5[0m[0;34m,[0m[0;36m6[0m[0;34m][0m[0;34m}[0m[0;34m)[0m[0;34m[0m[0;34m[0m[0m
[0;32m----> 7[0;31m [0massert_frame_equal[0m[0;34m([0m[0mdf1[0m[0;34m,[0m [0mdf2[0m[0;34m)[0m[0;34m[0m[0;34m[0m[0m
[0m
    [0;31m[... skipping hidden 2 frame][0m

[0;32m~/book/venv/lib/python3.8/site-packages/pandas/_libs/testing.pyx[0m in [0;36mpandas._libs.testing.assert_almost_equal[0;34m()[0m

[0;32m~/book/venv/lib/python3.8/site-packages/pandas/_libs/testing.pyx[0m in [0;36mpandas._libs.testing.assert_almost_equal[0;34m()[0m

[0;32m~/book/venv/lib/python3.8/site-packages/pandas/_testing/asserters.py[0m in [0;36mraise_assert_detail[0;34m(obj, message, left, right, diff, index_values)[0m
[1;32m    663[0m         [0mmsg[0m [0;34m+=[0m [0;34mf"\n[diff]: {diff}"[0m[0;34m[0m[0;34m[0m[0m
[1;32m    664[0m [0;34m[0m[0m
[0;32m--> 665[0;31m     [0;32mraise[0m [0mAssertionError[0m[0;34m([0m[0mmsg[0m[0;34m)[0m[0;34m[0m[0;34m[0m[0m
[0m[1;32m    666[0m [0;34m[0m[0m
[1;32m    667[0m [0;34m[0m[0m

[0;31mAssertionError[0m: DataFrame.iloc[:, 0] (column name="coll") are different

DataFrame.iloc[:, 0] (column name="coll") values are different (66.66667 %)
[index]: [0, 1, 2]
[left]:  [1, 2, 3]
[right]: [1, 3, 4]
AssertionError: DataFrame.iloc[:, 0] (column name="coll") are different

DataFrame.iloc[:, 0] (column name="coll") values are different (66.66667 %)
[index]: [0, 1, 2]
[left]:  [1, 2, 3]
[right]: [1, 3, 4]

